Workbook

Sheet Achievements
A1: Branch | B1: Cluster | C1: Order | D1: ID | E1: Name | F1: Clue (in_app hint) | G1: Criteria (Play Console description) | H1: Gilds | I1: Gild count | J1: Blurb (optional) | K1: Status | L1: XP | M1: D notes
A2: Tutorial | B2: Tutorial | C2: 1 | D2: first | E2: FIRST! | F2: _switch it on_ | G2: Switch achievements on from the achievements section. | H2: 2 | I2: 1 | J2: Congratulations, you've unlocked the Achievements! As a reward, your trophy room view has a gilded 2. So shiny! So rewarding! How many more numbers can you gild? Only one way to find out! (In the world of Primes, 2 comes 1st.) | K2: kept | L2: 20
A3: Tutorial | B3: Tutorial | C3: 2 | D3: exhaustive | E3: EXHAUSTIVE! | F3: _show the ones in between_ | G3: Switch on all integers in range. | H3: 1000 | I3: 1 | J3: You've discovered the many toggles that change the shape of the Pretty Number Machine. Nice! | K3: kept | L3: 20
A4: Tutorial | B4: Tutorial | C4: 3 | D4: parawhat | E4: PARAWHAT?! | F4: _pe_RAS_te_kee_ | G4: Turn on or adjust parastichy line visibility. | H4: 137 | I4: 1 | J4: Counting by prime multiples looks cool, and visualizing them was the initial motivation for Pretty Number Machine. Now you get to see them at the touch of a button. This is the texture of the numberline implicit in the concept of quantity. You're unlocking the arcane mysteries of the universe on a phone app! The future is wild! | K4: kept | L4: 20
A5: Tutorial | B5: Tutorial | C5: 4 | D5: art | E5: ART! | F5: _change how it looks, not what it is_ | G5: Change any appearance setting. | H5: 433 | I5: 1 | J5: Art cannot be explained, it must be EXPERIENCED! | K5: kept | L5: 20
A6: Tutorial | B6: Tutorial | C6: 5 | D6: bophades | E6: ORBS! | F6: _so big_ | G6: Take node size to its maximum. | H6: 8 | I6: 1 | J6: Wow, they're huge! | K6: kept | L6: 20
A7: Tutorial | B7: Tutorial | C7: 6 | D7: maximalist | E7: MAXIMALIST! | F7: _push the slider all the way_ | G7: Take the range slider to its maximum, 2500. | H7: 999 | I7: 1 | J7: So many! | K7: kept | L7: 20
A8: Tutorial | B8: Tutorial | C8: 7 | D8: ceiling | E8: CEILING! | F8: _the slider was lying_ | G8: Set the range to 10000. | H8: 997 | I8: 1 | J8: Okay let's not break your phone. | K8: kept | L8: 20
A9: Tutorial | B9: Tutorial | C9: 8 | D9: zoomies | E9: ZOOMIES! | F9: _faster, all the way_ | G9: Turn morph speed up to maximum. | H9: 88, 121 | I9: 2 | J9: 88 miles an hour, and 1.21 gigawatts. | K9: kept | L9: 20
A10: Tutorial | B10: Tutorial | C10: 9 | D10: boing | E10: BOING! | F10: _wait for the bottom_ | G10: Let the morph reach the Spring form. | H10: 6 | I10: 1 | J10: Boingyboingyboingy! 6 looks kinda like a spring, right? | K10: kept | L10: 20
A11: Tutorial | B11: Tutorial | C11: 10 | D11: trippy | E11: TRIPPY! | F11: _there is a button for this_ | G11: Press Dazzle. | H11: 815 | I11: 1 | J11: Far out dude, look at all the colors! You know, like, sunflowers are like a lotus if you really think about it man. Anyway, are you big into music? | K11: kept | L11: 20
A12: Tutorial | B12: Tutorial | C12: 11 | D12: nerd | E12: NERD! | F12: _drag the classroom across_ | G12: Open the classroom lens. | H12: 42 | I12: 1 | J12: Knowing the name of a thing may not tell you much about its intrinsic nature, but precise jargon sure helps in conversation! | K12: kept | L12: 20
A13: Tutorial | B13: Tutorial | C13: 12 | D13: ouch | E13: OUCH! | F13: _take hold of the Sun_ | G13: With physics on, drag node 0. | H13: 149 | I13: 1 | J13: Oof, you okay? Sun hot. | K13: kept | L13: 20
A14: Tutorial | B14: Tutorial | C14: 13 | D14: oops | E14: OOPS! | F14: _make the springs disagree_ | G14: Get 20 or more nodes further than twice their rest distance from the Sun. | H14: 641 | I14: 1 | J14: Physics allows for stuff to get weird. | K14: kept | L14: 20
A15: Tutorial | B15: Tutorial | C15: 14 | D15: night | E15: NIGHT! | F15: _put out the Sun_ | G15: Switch off the zero node. | H15: 354 | I15: 1 | J15: Uhh, who turned out the lights? | K15: kept | L15: 20
A16: Tutorial | B16: Tutorial | C16: 15 | D16: void | E16: VOID! | F16: _take every prime away_ | G16: Deselect every prime. | H16: nothing | I16: 0 | J16: Turn off every prime and two numbers are left: 0 and 1. They are the only ones not built out of primes. | K16: kept | L16: 20
A17: Tutorial | B17: Tutorial | C17: 16 | D17: empty-set | E17: EMPTY SET! | F17: _then take away what was left_ | G17: Deselect every prime and switch off both 0 and 1. | H17: 86 | I17: 1 | J17: Nothing at all. In maths that is a real thing with its own name and its own symbol. | K17: kept | L17: 20
A18: Math | B18: Series | D18: fibonacci | E18: FIBONACCI! | F18: _how nature counts_ | G18: Select exactly the five Fibonacci primes and nothing else. | H18: Fibonacci numbers to 987 | I18: 14 | J18: The Fibonacci numbers are 1, 1, 2, 3, 5, 8, 13, 21 and so on. Add the last two to get the next. Can be found on the spirals of a pinecone. | K18: kept | L18: 20
A19: Math | B19: Series | D19: lucas | E19: LUCAS! | F19: _fibonacci, but different_ | G19: Select exactly 2, 3, 7, 11, 29 and 47. | H19: Lucas numbers to 843 | I19: 14 | J19: The Lucas numbers follow the same rule as the Fibonacci numbers -- add the last two to get the next -- but start 2, 1 instead of 1, 1. You get a completely different sequence that still grows at the golden ratio. The two are twins: change only where you begin. | K19: kept | L19: 20
A20: Math | B20: Series | D20: triangular | E20: TRIANGULAR! | F20: _stack the coins_ | G20: Set the range to 990. | H20: triangular numbers to 990 | I20: 43 | J20: Stack coins in a triangle: 1, then 3, then 6, then 10. The nth one is n(n+1)/2, and it is also the number of handshakes in a room of n+1 people. 990 is the largest that fits. | K20: new | L20: 20
A21: Math | B21: Series | D21: squares | E21: SQUARES! | F21: _the odd ones out_ | G21: Set the range to 961. | H21: square numbers to 961 | I21: 30 | J21: Divisors come in pairs: if d divides n, so does n/d. So every number has an even count of divisors -- except when d and n/d are the same number, which happens only for a perfect square. The squares are the only numbers with an odd number of divisors. That is the hundred-lockers puzzle, and the answer is 1, 4, 9, 16, 25, 36, 49, 64, 81, 100. | K21: reworked | L21: 20 | M21: hint improve?
A22: Math | B22: Series | D22: cubes | E22: CUBES! | F22: _n by n by n_ | G22: Set the range to 729. | H22: 8, 27, 64, 125, 216, 343, 512, 729, 1000 | I22: 9 | K22: new | L22: 20 | M22: add blurb
A23: Math | B23: Series | D23: double | E23: DOUBLE! | F23: _again, and again_ | G23: Set the range to 512. | H23: 2, 4, 8, 16, 32, 64, 128, 256, 512 | I23: 9 | J23: Keep doubling. Because a node sits at a distance proportional to the square root of its number, doubling pushes each one about 1.41 times further out than the last -- so they spiral outward with widening gaps, while everything else crowds together. | K23: new | L23: 20
A24: Math | B24: Series | D24: factorial | E24: FACTORIAL! | F24: _one times two times three_ | G24: Set the range to 720. | H24: 2, 6, 24, 120, 720 | I24: 5 | J24: Multiply 1 by 2 by 3 by 4 and so on. It gets away from you almost immediately: only five of them fit under a thousand, and the next one is 5,040. | K24: new | L24: 20 | M24: the various set-range-to as inputs doesn't make sense for unlocking a series. These need to change or go away. Also, the app is for developing intuition and having fun, not feeling behind if you don't already know something. Perhaps all these named ones should go away as they aren't based on the joy of discovery, but the application of external knowledge.
A25: Math | B25: Series | D25: ramanujan | E25: RAMANUJAN! | F25: _more factors than anything smaller_ | G25: Set the range to 840. | H25: highly composite numbers to 840 | I25: 14 | J25: A highly composite number has more divisors than every number below it. 840 has thirty-two, more than any number under a thousand. Ramanujan named and catalogued them in 1915. They are the exact opposite of primes: primes have no factors at all, and these have as many as it is possible to have. | K25: kept | L25: 20
A26: Math | B26: Series | D26: perfect | E26: PERFECT! | F26: _equal to the sum of its parts_ | G26: Select exactly 2, 3, 7 and 31. | H26: 2, 3, 7, 31, 6, 28, 496 | I26: 7 | J26: A perfect number equals the sum of its proper divisors: 6 = 1+2+3, and 28 = 1+2+4+7+14. Euclid proved that 2^(p-1)(2^p - 1) is perfect whenever 2^p - 1 is prime, and Euler proved every even perfect number has that form. So each one is built from a Mersenne prime: 6 = 2x3, 28 = 4x7, 496 = 16x31. Only three exist below 1000; the next is 8128. Whether any odd perfect number exists is still open after two thousand years. | K26: kept | L26: 20
A27: Math | B27: Series | D27: euclid | E27: EUCLID! | F27: _one more than all of them multiplied_ | G27: Set the range to 211. | H27: 210, 211 | I27: 2 | J27: Multiply the first four primes: 2 x 3 x 5 x 7 = 210. Add one and you get 211, which is prime. That is Euclid's argument, and it never runs out: multiply any finite list of primes together, add one, and the result is divisible by none of them. So no finite list can be all of them. | K27: new | L27: 20
A28: Math | B28: Series | D28: amicable | E28: AMICABLE! | F28: _each is the other's sum_ | G28: Select exactly 2 and 71. | H28: 220, 284 | I28: 2 | J28: Add up the divisors of 220 and you get 284. Add up the divisors of 284 and you get 220. They are the smallest amicable pair, they are the only one under a thousand, and people have been passing them back and forth as tokens of friendship since Pythagoras. | K28: new | L28: 20
A29: Math | B29: Primes | D29: twinning | E29: TWINNING! | F29: _one even number between them_ | G29: Select exactly two primes that differ by 2. | H29: all twin primes to 1000 | I29: 69 | J29: Twin primes are only 2 apart, like 11 and 13. Nobody knows whether they ever stop. People have been trying to find out since 1849. | K29: kept | L29: 20 | M29: See, this is fun because it let's the user arrive at something neat without having to come in with outside knowledge. It's a learning opportunity and it is figure-out-able from the clue.
A30: Math | B30: Primes | D30: cousins | E30: COUSINS! | F30: _four apart_ | G30: Select exactly two primes that differ by 4. | H30: all cousin primes to 1000 | I30: 81 | J30: Primes 4 apart are called cousins. That is the real name. | K30: kept | L30: 20
A31: Math | B31: Primes | D31: sexy | E31: SEXY! | F31: _it really is Latin_ | G31: Select exactly two primes that differ by 6. | H31: all sexy primes to 1000 | I31: 120 | J31: Primes 6 apart are called sexy primes. Sex is Latin for six. Mathematicians named these and nobody stopped them. | K31: kept | L31: 20
A32: Math | B32: Primes | D32: germain | E32: GERMAIN! | F32: _double it, add one_ | G32: Select exactly two primes p and q where q = 2p+1. | H32: all Sophie Germain primes to 1000 | I32: 37 | J32: Pick a prime, double it, add 1. If that is prime too, the first one is a Sophie Germain prime. Sophie Germain had to sign her work with a man's name to get anyone to read it. She was one of the best mathematicians of her time. | K32: kept | L32: 20
A33: Math | B33: Primes | D33: emirp | E33: EMIRP! | F33: _read it the other way_ | G33: Select exactly two primes that are each other's digit reversal. | H33: all emirps to 1000 | I33: 36 | J33: Write a prime backwards. If you get a different prime, it is an emirp -- which is 'prime' spelled backwards. There are four pairs in the grid: 13 and 31, 17 and 71, 37 and 73, 79 and 97. | K33: kept | L33: 20
A34: Math | B34: Primes | D34: happy | E34: HAPPY! | F34: _square the digits, and again_ | G34: Select exactly the nine happy primes. | H34: all happy primes to 1000 | I34: 35 | J34: Square each digit, add them up, repeat. Every number eventually settles into a loop, because above 1000 the result always shrinks. In base 10 there are only two destinations: the fixed point 1, or an eight-step cycle. The ones that reach 1 are called happy. Note that this is a fact about base 10, not about the integers. | K34: kept | L34: 20
A35: Math | B35: Primes | D35: euler | E35: EULER! | F35: _forty in a row, then it breaks_ | G35: Select exactly the ten primes generated by n^2+n+41 for n = 0..9. | H35: Euler polynomial primes to 1000 | I35: 31 | J35: Euler's polynomial n^2 + n + 41 is prime for every n from 0 to 39. This is not luck. It fails at n = 40, where 40^2 + 40 + 41 comes to 41 x 41 -- which it had to, because putting n = 41 in makes every term a multiple of 41. | K35: kept | L35: 20
A36: Math | B36: Primes | D36: mersenne | E36: MERSENNE! | F36: _one less than a power of two_ | G36: Select exactly 3, 7, 31 and 127. | H36: 3, 7, 31, 127 | I36: 4 | J36: Take a power of two and subtract one: 4-1 = 3, 8-1 = 7, 32-1 = 31, 128-1 = 127. When the result is prime it is called a Mersenne prime, and the exponent has to be prime for it to work at all. All four that fit in this grid are here. Every even perfect number is built from one of them. | K36: new | L36: 20
A37: Math | B37: Primes | D37: fermat | E37: FERMAT! | F37: _and together, one byte_ | G37: Select exactly 3, 5 and 17. | H37: 3, 5, 17, 255, 257 | I37: 5 | J37: The Fermat primes are 3, 5, 17, 257 and 65537, and nobody has ever found another. Gauss proved you can construct a regular polygon with compass and straightedge exactly when its number of sides involves these -- which is why a 17-sided figure is possible and a 7-sided one is not. And 3 x 5 x 17 = 255, which is one byte. | K37: new | L37: 20
A38: Math | B38: Primes | D38: neat | E38: NEAT! | F38: _almost a straight line_ | G38: Two primes selected, one of them 89, with the range at least 178. | H38: 89 and its parastichy line | I38: 1 | J38: Each node sits a little further round the circle than the one before. Turn that far 89 times and you land almost exactly back where you started. So the multiples of 89 stack up in a nearly straight line -- the only spoke in the whole figure. | K38: kept | L38: 20
A39: Math | B39: Primes | D39: louder | E39: LOUDER! | F39: _nothing but ones_ | G39: Select exactly 11. | H39: 11 | I39: 1 | J39: 11 is a repunit: written with nothing but 1s. It is the smallest two-digit prime, and the only two-digit prime that reads the same backwards. | K39: kept | L39: 20
A40: Math | B40: Primes | D40: smart | E40: SMART! | F40: _the same both ways_ | G40: Select exactly 101 and view it through the classroom lens. | H40: 101 | I40: 1 | J40: 101 reads the same forwards and backwards. It is the smallest three-digit prime. | K40: kept | L40: 20
...

Sheet Summary
A1: Pretty Number Machine - achievements v2
A2: Draft, 2026-08-21. Companion to docs/ACHIEVEMENTS-V2.md, which holds the design reasoning.
A4: Cluster | B4: Count | C4: XP each | D4: XP total
A5: Tutorial | B5: =COUNTIF(Achievements!$B$2:$B$85,A5) -> 16 | C5: 20 | D5: =B5*C5 -> 320
A6: Series | B6: =COUNTIF(Achievements!$B$2:$B$85,A6) -> 11 | C6: 20 | D6: =B6*C6 -> 220
A7: Primes | B7: =COUNTIF(Achievements!$B$2:$B$85,A7) -> 12 | C7: 20 | D7: =B7*C7 -> 240
A8: Puzzles | B8: =COUNTIF(Achievements!$B$2:$B$85,A8) -> 5 | C8: 20 | D8: =B8*C8 -> 100
A9: Meme | B9: =COUNTIF(Achievements!$B$2:$B$85,A9) -> 16 | C9: 20 | D9: =B9*C9 -> 320
A10: Lore | B10: =COUNTIF(Achievements!$B$2:$B$85,A10) -> 10 | C10: 20 | D10: =B10*C10 -> 200
A11: Geek | B11: =COUNTIF(Achievements!$B$2:$B$85,A11) -> 10 | C11: 20 | D11: =B11*C11 -> 200
A12: Greeks | B12: =COUNTIF(Achievements!$B$2:$B$85,A12) -> 3 | C12: 20 | D12: =B12*C12 -> 60
A13: Capstone | B13: =COUNTIF(Achievements!$B$2:$B$85,A13) -> 1 | C13: 20 | D13: =B13*C13 -> 20
A14: TOTAL | B14: =SUM(B5:B13) -> 84 | D14: =SUM(D5:D13) -> 1680
A16: Play Games XP cap | B16: 2000
A17: Held in reserve | B17: =B16-D14 -> 320
A20: NOTES
A21: XP is 20 per achievement, in blue where it is an input. The cap of 2000 is Play's, across all achievements combined.
A22: Reserve matters: achievements can be added after publication but effectively never removed, so spending the whole budget is the one mistake that cannot be corrected later.
A23: UNVERIFIED: whether Play Console constrains individual XP to particular increments or a per-achievement maximum. Check before this hardens.
A25: Criteria is the Play Console description and is PUBLIC in the Play Games app. It is a separate string from the in-app clue, which stays cryptic.
A26: Clue is what a locked row shows. Tapping a locked row previews its gild set on the figure - the two are independent routes to the same answer.
A27: Blurb is shown only once earned. Blank means none is needed.
A29: OPEN: SIXES! gilds 6 alone here. Gilding every multiple of 6 would be 166 nodes, more than SEXY! at 120, which is currently the largest set in the design.
A30: OPEN: GOLDBACH!'s exact predicate - whether the range must equal the sum or merely be even.
A31: OPEN: STUBBORN! (196, the Lychrel candidate) as a sixth puzzle.
