Workbook

Sheet Read me
A1: Pretty Number Machine - achievements v7 proposal
A2: Generated from the live achievements-data.js, not from achievements-v6.xlsx.
A4: What this is
A5: All 101 current achievements plus 5 proposed additions, assessed against the design rubric below. Nothing here is implemented - this is the sheet to argue with.
A7: The rubric
A8: 1. Never tax a player for lack of education. | B8: Insider knowledge may be REWARDED but must never be REQUIRED. A clue that only a specialist can enter is a wall, not a puzzle.
A9: 2. The payoff must be an 'ahhh', not a 'huh, yeah I guess'. | B9: In practice this means the nodes that light up should not be the nodes you tapped. Selecting {2,3,37} and watching 666 assemble is the app teaching you what factorisation feels like. Selecting {5,53} and lighting 5 and 53 teaches nothing.
A10: 3. The clue must actually help. | B10: It may disguise; it may not merely withhold. Afrit's dictum, already in ACHIEVEMENTS.md §4 - the change here is applying it to the ones that were leaning on the locked-row preview that got cut.
A11: 4. Some are just for funsies. | B11: A single-node joke whose payoff is recognition is fine and does not need a pattern.
A13: Status column
A14: KEEP | B14: No change proposed.
A15: FIX-CLUE | B15: Trigger and gild stand; the clue does not get a player in. See 'Proposed clue'.
A16: FIX-GILD | B16: Trigger and clue stand; the payoff is flat. See 'Proposed gild'. Costs no slot.
A17: DROP | B17: Recommended cut. Funds an addition - see 'Pays for'.
A18: REVIEW | B18: Genuinely your call. The trade-off is stated in Notes; I have not picked a side.
A19: NEW | B19: Proposed addition, accepted.
A20: REJECTED | B20: Proposed addition you turned down. Kept in the sheet as a record of the decision.
A22: Column 'In A?'
A23: Scenario A | B23: Y = in the proposed list. REVISED after your first pass: GALLERY! accepted, DOUBLING! and THIRD! rejected. That makes 3 additions against 2 drops, so the list currently reads 102 and needs one more drop - see DECISION NEEDED on the Distribution tab. Everything marked REVIEW is still Y; it stays unless you say otherwise.
A25: Reading order
A26: Distribution | B26: Start here if you only read one tab. Cluster balance, current vs proposed, and the argument about Dial.
A27: Proposal | B27: The full 106-row table, now with a verified 'Proposed link' column.
A28: UI changes | B28: The three asks that are not per-achievement data: showing criteria on unlock, the trophy-room-on-tap question, and how links should be stored.
A29: Collisions | B29: A correctness bug found while reviewing, unrelated to your rubric but worth fixing in the same pass.

Sheet Proposal
A1: No | B1: ID | C1: Name | D1: Branch | E1: Cluster | F1: Status | G1: In A? | H1: Pays for | I1: Trigger now | J1: Clue now | K1: Proposed clue | L1: Gild now | M1: Proposed gild | N1: Payoff | O1: Newbie route | P1: Collision | Q1: Proposed link | R1: Notes / reasoning
A2: 1 | B2: first | C2: FIRST! | D2: Tutorial | E2: Tutorial | F2: KEEP | G2: Y | I2: dom | J2: -switch it on- | L2: 2 | N2: Joke | O2: Open | R2: The on-ramp. Nothing to change.
A3: 2 | B3: exhaustive | C3: EXHAUSTIVE! | D3: Tutorial | E3: Tutorial | F3: KEEP | G3: Y | I3: dom | J3: -show the ones in between- | L3: 1000 | N3: Pattern | O3: Open | Q3: Natural number | R3: Teaches the dark field, which every later gild depends on being able to see.
A4: 3 | B4: parawhat | C4: PARAWHAT?! | D4: Tutorial | E4: Tutorial | F4: KEEP | G4: Y | I4: dom | J4: -pe-RAS-te-kee- | L4: 34, 55 | N4: New nodes | O4: Open | Q4: Phyllotaxis | R4: Gilds 34 and 55 - a quiet Fibonacci wink long before FIBONACCI! exists.
A5: 4 | B5: art | C5: ART! | D5: Tutorial | E5: Tutorial | F5: KEEP | G5: Y | I5: dom | J5: -change how it looks, not what it is- | L5: 433 | N5: Joke | O5: Open
A6: 5 | B6: bophades | C6: ORBS! | D6: Tutorial | E6: Tutorial | F6: KEEP | G6: Y | I6: dom | J6: -so big- | L6: 8 | N6: Joke | O6: Open
A7: 6 | B7: maximalist | C7: MAXIMALIST! | D7: Tutorial | E7: Tutorial | F7: KEEP | G7: Y | I7: dom | J7: -push the slider all the way- | L7: 999 | N7: Joke | O7: Open | R7: The slider-to-max lesson. Does CEILING!’s job without the cost.
A8: 7 | B8: ceiling | C8: CEILING! | D8: Tutorial | E8: Tutorial | F8: DROP | G8: N | H8: DECOMPOSE! | I8: state | J8: -the slider was lying- | L8: 997 | N8: Joke | O8: Open | R8: Duplicates MAXIMALIST! - both are "push the slider further". Only configuration in the app that falls below refresh cap: 26.7 fps on a Pixel 7 (ACHIEVEMENTS.md §9). Its own blurb is "Okay let’s not break your phone", so the tutorial is rewarding degradation of the app. Frees the slot for DECOMPOSE!.
A9: 8 | B9: zoomies | C9: ZOOMIES! | D9: Tutorial | E9: Tutorial | F9: KEEP | G9: Y | I9: state | J9: -faster, all the way- | L9: 88, 121 | N9: Joke | O9: Open
A10: 9 | B10: boing | C10: BOING! | D10: Tutorial | E10: Tutorial | F10: KEEP | G10: Y | I10: sampled | J10: -wait for the bottom- | L10: 6 | N10: Joke | O10: Open
A11: 10 | B11: trippy | C11: TRIPPY! | D11: Tutorial | E11: Tutorial | F11: KEEP | G11: Y | I11: dom | J11: -there is a button for this- | L11: 815 | N11: Joke | O11: Open
A12: 11 | B12: nerd | C12: NERD! | D12: Tutorial | E12: Tutorial | F12: KEEP | G12: Y | I12: state | J12: -drag the classroom across- | L12: 42 | N12: Joke | O12: Open | R12: Rewards OPENING the lens only. Tapping a node - the thing the lens exists for - goes unrewarded today. DECOMPOSE! is the second half of this, not a duplicate of it.
A13: 12 | B13: ouch | C13: OUCH! | D13: Tutorial | E13: Tutorial | F13: KEEP | G13: Y | I13: event | J13: -take hold of the Sun- | L13: 149 | N13: Joke | O13: Open
A14: 13 | B14: oops | C14: OOPS! | D14: Tutorial | E14: Tutorial | F14: KEEP | G14: Y | I14: sampled | J14: -make the springs disagree- | L14: 641 | N14: Joke | O14: Open
A15: 14 | B15: night | C15: NIGHT! | D15: Tutorial | E15: Tutorial | F15: KEEP | G15: Y | I15: state | J15: -put out the Sun- | L15: 354 | N15: Joke | O15: Open
A16: 15 | B16: void | C16: VOID! | D16: Tutorial | E16: Tutorial | F16: KEEP | G16: Y | I16: state | J16: -take every prime away- | L16: - | N16: Joke | O16: Open | Q16: 1 | R16: Blurb is a real intuition beat: 0 and 1 are the only numbers not built out of primes.
A17: 16 | B17: empty-set | C17: EMPTY SET! | D17: Tutorial | E17: Tutorial | F17: KEEP | G17: Y | I17: state | J17: -then take away what was left- | L17: 86 | N17: Joke | O17: Open | Q17: Empty set
A18: 17 | B18: fibonacci | C18: FIBONACCI! | D18: Math | E18: Series | F18: KEEP | G18: Y | I18: select exactly {2, 3, 5, 13, 89} | J18: -how nature counts- | L18: 2, 3, 5, 8, 13 ... (14 nodes) | N18: Pattern | O18: Open | Q18: Fibonacci sequence | R18: Model achievement: select 5 primes, 14 nodes light up that you did not select.
A19: 18 | B19: lucas | C19: LUCAS! | D19: Math | E19: Series | F19: FIX-CLUE | G19: Y | I19: select exactly {2, 3, 7, 11, 29, 47} | J19: -fibonacci, but different- | K19: -two and one, then add as before- | L19: 2, 3, 4, 7, 11 ... (14 nodes) | N19: Pattern | O19: Closed | Q19: Lucas number | R19: The clearest failure of the no-education-tax rule. "-fibonacci, but different-" offers no route in at all: you must already know the Lucas sequence AND which of its members are prime. The proposed clue states the rule and the seeds, so the work becomes derivation rather than recall - a fair professor achievement instead of a wall.
A20: 19 | B20: perfect | C20: PERFECT! | D20: Math | E20: Series | F20: KEEP | G20: Y | I20: select exactly {2, 3, 7, 31} | J20: -equal to the sum of its parts- | L20: 2, 3, 7, 31, 6 ... (7 nodes) | N20: New nodes | O20: Lookup | Q20: Perfect number | R20: Good: 6, 28 and 496 appear and you selected none of them. Route is fair - take the perfect numbers you know and select their factors.
A21: 20 | B21: twinning | C21: TWINNING! | D21: Math | E21: Primes | F21: KEEP | G21: Y | I21: state | J21: -one even number between them- | L21: 3, 5, 7, 11, 13 ... (69 nodes) | N21: Pattern | O21: Open | Q21: Twin prime | R21: Best in class. The clue alone is sufficient and 69 nodes answer.
A22: 21 | B22: cousins | C22: COUSINS! | D22: Math | E22: Primes | F22: KEEP | G22: Y | I22: state | J22: -four apart- | L22: 3, 7, 11, 13, 17 ... (81 nodes) | N22: Pattern | O22: Open | Q22: Cousin prime
A23: 22 | B23: sexy | C23: SEXY! | D23: Math | E23: Primes | F23: KEEP | G23: Y | I23: state | J23: -six apart, and that is the real name- | L23: 5, 7, 11, 13, 17 ... (120 nodes) | N23: Pattern | O23: Open | Q23: Sexy primes
A24: 23 | B24: germain | C24: GERMAIN! | D24: Math | E24: Primes | F24: KEEP | G24: Y | I24: state | J24: -double it, add one- | L24: 2, 3, 5, 11, 23 ... (37 nodes) | N24: Pattern | O24: Open | Q24: Safe and Sophie Germain primes | R24: "-double it, add one-" is the model relational clue.
A25: 24 | B25: emirp | C25: EMIRP! | D25: Math | E25: Primes | F25: KEEP | G25: Y | I25: state | J25: -read it the other way- | L25: 13, 17, 31, 37, 71 ... (36 nodes) | N25: Pattern | O25: Open | Q25: Emirp
A26: 25 | B26: mersenne | C26: MERSENNE! | D26: Math | E26: Primes | F26: DROP | G26: N | H26: TEMPTED! | I26: select exactly {3, 7, 31, 127} | J26: -one less than a power of two- | L26: 3, 7, 31, 127 | N26: Self | O26: Lookup | Q26: Mersenne prime | R26: Same idea as PERFECT! (2^p - 1), and the weaker of the two: PERFECT! reveals 6, 28 and 496, while MERSENNE! gilds back the four primes you just tapped. PERFECT!’s blurb already explains Mersenne primes, so the subject survives the cut. Frees the slot for TEMPTED!.
A27: 26 | B27: fermat | C27: FERMAT! | D27: Math | E27: Primes | F27: KEEP | G27: Y | I27: select exactly {3, 5, 17} | J27: -one more than a power of two- | L27: 3, 5, 17, 255, 257 | N27: New nodes | O27: Lookup | Q27: Fermat number | R27: Select three primes, 255 and 257 appear. The payoff works.
A28: 27 | B28: neat | C28: NEAT! | D28: Math | E28: Primes | F28: KEEP | G28: Y | I28: state | J28: -almost a straight line- | L28: 89 | N28: New nodes | O28: Open | Q28: Golden angle | R28: The only line drawn in the gallery. Worth protecting exactly as is.
A29: 28 | B29: louder | C29: LOUDER! | D29: Math | E29: Primes | F29: KEEP | G29: Y | I29: select exactly {11} | J29: -these ones go to- | L29: 11 | N29: Joke | O29: Open | Q29: Up to eleven | R29: Spinal Tap. No blurb - the joke is the whole payload.
A30: 29 | B30: smart | C30: SMART! | D30: Math | E30: Primes | F30: KEEP | G30: Y | I30: state | J30: -intro class- | L30: 101 | N30: Joke | O30: Open | Q30: 101 (number)
A31: 30 | B31: balanced | C31: BALANCED! | D31: Math | E31: Primes | F31: FIX-GILD | G31: Y | I31: select exactly {5, 53} | J31: -exactly halfway between its neighbours- | L31: 5, 53 | M31: 3, 5, 7, 47, 53, 59 | N31: Self | O31: Open | Q31: Balanced prime | R31: The idea is lovely and findable by eye - 3-5-7 is right there. The payoff is flat: you tap 5 and 53, and 5 and 53 light up. Gilding the neighbours draws the symmetry the blurb is describing.
A32: 31 | B32: stride | C32: STRIDE! | D32: Math | E32: Primes | F32: FIX-GILD | G32: Y | I32: select exactly {113, 127} | J32: -the widest step- | L32: 113, 127 | M32: 113-127 inclusive (15 nodes) | N32: Self | O32: Open | Q32: Prime gap | R32: The clue "-the widest step-" describes a GAP and the gild shows only its two endpoints. Gilding the run makes you see the hole in the number line, which is the whole point.
A33: 32 | B33: all-prime | C33: PRIME DIGITS! | D33: Math | E33: Primes | F33: FIX-GILD | G33: Y | I33: select exactly {2, 3, 5, 7, 23, 37, 53, 73} | J33: -every digit too- | L33: 2, 3, 5, 7, 23 ... (8 nodes) | M33: all 84 numbers under 1000 written only in 2/3/5/7 | N33: Self | O33: Lookup | Q33: Decimal | R33: Eight taps, and the same eight light up. The blurb then undercuts its own achievement - "a fact about writing in base ten rather than about the numbers themselves". Gilding all 84 prime-digit numbers under 1000 turns that from an apology into a visible scatter, making the base-ten point the payoff instead of a caveat.
A34: 33 | B34: super-prime | C34: SUPERPRIME! | D34: Math | E34: Primes | F34: REVIEW | G34: Y | I34: select exactly {3, 5, 11, 17, 31, 41, 59, 67, 83, 109, 127} | J34: -count the primes and land on one- | L34: 3, 5, 11, 17, 31 ... (11 nodes) | N34: Self | O34: Open | Q34: Super-prime | R34: Split verdict - your call. The IDEA is the most intuitive thing in the cluster: count along the panel and land on a prime position, no education required, and the blurb says exactly that. The EXECUTION is 11 taps returning the same 11 nodes - the worst effort-to-payoff ratio in the list. No gild set fixes it, because here the answer IS the selection. Keep it as the deliberate completionist grind, or drop it and spend the slot on Puzzles.
A35: 34 | B35: goldbach | C35: GOLDBACH! | D35: Math | E35: Puzzles | F35: KEEP | G35: Y | I35: state | J35: -two make an even- | L35: 4, 6, 8, 10, 12 ... (123 nodes) | N35: Pattern | O35: Open | Q35: Goldbach's conjecture | R35: Exactly the brief: you verify a 1742 conjecture by hand and 123 nodes answer.
A36: 35 | B36: collatz | C36: COLLATZ! | D36: Math | E36: Puzzles | F36: FIX-CLUE | G36: Y | I36: select exactly {13, 67} | J36: -the long way down- | K36: -halve it, or triple it and add one- | L36: 871 | N36: New nodes | O36: Closed | Q36: Collatz conjecture | R36: The payoff is fine - 871 appears. The route is not: "-the long way down-" cannot get anyone to 871 unless they already know it is the under-1000 record holder. Naming the rule makes Collatz lookup-able - it is famous pop maths - and factoring 871 is then ordinary app work.
A37: 36 | B37: run | C37: RUN! | D37: Math | E37: Puzzles | F37: KEEP | G37: Y | I37: state | J37: -a run of them adds up to another- | L37: 17, 23, 31, 41, 53 ... (14 nodes) | N37: Pattern | O37: Open | Q37: Prime number
A38: 37 | B38: stairs | C38: STAIRS! | D38: Math | E38: Puzzles | F38: KEEP | G38: Y | I38: state | J38: -three evenly spaced- | L38: 3, 5, 7 | N38: New nodes | O38: Open | Q38: Primes in arithmetic progression | R38: Blurb is a genuine "ahhh": why 3-5-7 is the only consecutive triple that can ever be evenly spaced.
A39: 38 | B39: square-up | C39: SQUARE UP! | D39: Math | E39: Puzzles | F39: KEEP | G39: Y | I39: state | J39: -two that add to a square- | L39: 9, 16, 25, 36, 49 ... (10 nodes) | N39: Pattern | O39: Open | Q39: Square number
A40: 39 | B40: nice | C40: NICE! | D40: Culture | E40: Meme | F40: KEEP | G40: Y | I40: select exactly {3, 23} | J40: -nice- | L40: 69 | N40: New nodes | O40: Open | Q40: 69 (number)
...

Sheet Distribution
A1: Cluster distribution - current vs Scenario A
A2: Counts are live: they read the Proposal tab, so editing a Status or an In A? there updates them here.
A4: Branch | B4: Cluster | C4: Now | D4: Scenario A | E4: Change | F4: % of list (A) | G4: Assessment
A5: Tutorial | B5: Tutorial | C5: =COUNTIFS(Proposal!$E$2:$E$107,$B5,Proposal!$F$2:$F$107,"<>NEW") | D5: =COUNTIFS(Proposal!$E$2:$E$107,$B5,Proposal!$G$2:$G$107,"Y") | E5: =D5-C5 | F5: =IF($D$16=0,0,D5/$D$16) | G5: GROWS 16 -> 17. Absorbs both additions and loses CEILING!. This is the right place for growth: every Tutorial entry is a feature that otherwise goes undiscovered, and two of the app's best features - decomposition and the ad shop - currently have nothing pointing at them.
A6: Math | B6: Series | C6: =COUNTIFS(Proposal!$E$2:$E$107,$B6,Proposal!$F$2:$F$107,"<>NEW") | D6: =COUNTIFS(Proposal!$E$2:$E$107,$B6,Proposal!$G$2:$G$107,"Y") | E6: =D6-C6 | F6: =IF($D$16=0,0,D6/$D$16) | G6: Holds at 3. Small but each one gilds a whole sequence, so the payoff density is the highest in the list.
A7: Math | B7: Primes | C7: =COUNTIFS(Proposal!$E$2:$E$107,$B7,Proposal!$F$2:$F$107,"<>NEW") | D7: =COUNTIFS(Proposal!$E$2:$E$107,$B7,Proposal!$G$2:$G$107,"Y") | E7: =D7-C7 | F7: =IF($D$16=0,0,D7/$D$16) | G7: SHRINKS 14 -> 13 on the MERSENNE! cut. Still the largest Math cluster and the healthiest one: the five relational entries (TWINNING!, COUSINS!, SEXY!, GERMAIN!, EMIRP!) are the best achievements in the app by your rubric - clue alone is sufficient, and 37-120 nodes answer.
A8: Math | B8: Puzzles | C8: =COUNTIFS(Proposal!$E$2:$E$107,$B8,Proposal!$F$2:$F$107,"<>NEW") | D8: =COUNTIFS(Proposal!$E$2:$E$107,$B8,Proposal!$G$2:$G$107,"Y") | E8: =D8-C8 | F8: =IF($D$16=0,0,D8/$D$16) | G8: UNDERWEIGHT at 5. This is the cluster that most directly does what you described - GOLDBACH!, STAIRS! and RUN! build intuition about integers with no education required - and it is the second smallest in the list. First place to spend any slot you free.
A9: Culture | B9: Meme | C9: =COUNTIFS(Proposal!$E$2:$E$107,$B9,Proposal!$F$2:$F$107,"<>NEW") | D9: =COUNTIFS(Proposal!$E$2:$E$107,$B9,Proposal!$G$2:$G$107,"Y") | E9: =D9-C9 | F9: =IF($D$16=0,0,D9/$D$16) | G9: Holds at 13. Deliberately the smallest Culture cluster per §3 (jokes age, and Play Games will not let you remove one later). MEME! is the entry that tests that rule.
A10: Culture | B10: Lore | C10: =COUNTIFS(Proposal!$E$2:$E$107,$B10,Proposal!$F$2:$F$107,"<>NEW") | D10: =COUNTIFS(Proposal!$E$2:$E$107,$B10,Proposal!$G$2:$G$107,"Y") | E10: =D10-C10 | F10: =IF($D$16=0,0,D10/$D$16) | G10: Holds at 12. Healthy - mostly factor-selection with recognisable targets. Note that 4 of the 13 blurb-less achievements live here, and they are the most inside references in the list (THELEMA!/WHOLE! above all).
A11: Culture | B11: Geek | C11: =COUNTIFS(Proposal!$E$2:$E$107,$B11,Proposal!$F$2:$F$107,"<>NEW") | D11: =COUNTIFS(Proposal!$E$2:$E$107,$B11,Proposal!$G$2:$G$107,"Y") | E11: =D11-C11 | F11: =IF($D$16=0,0,D11/$D$16) | G11: Holds at 16, the largest cluster in the list, and it earns it: nearly every entry is recognise-the-number, factor-it, watch-it-appear. The core loop, repeated with good material.
A12: Culture | B12: Calendar | C12: =COUNTIFS(Proposal!$E$2:$E$107,$B12,Proposal!$F$2:$F$107,"<>NEW") | D12: =COUNTIFS(Proposal!$E$2:$E$107,$B12,Proposal!$G$2:$G$107,"Y") | E12: =D12-C12 | F12: =IF($D$16=0,0,D12/$D$16) | G12: Holds at 8. Cohesive and universally accessible - days, months, moons. Nobody needs an education for these, which is exactly the brief.
A13: Culture | B13: Dial | C13: =COUNTIFS(Proposal!$E$2:$E$107,$B13,Proposal!$F$2:$F$107,"<>NEW") | D13: =COUNTIFS(Proposal!$E$2:$E$107,$B13,Proposal!$G$2:$G$107,"Y") | E13: =D13-C13 | F13: =IF($D$16=0,0,D13/$D$16) | G13: THE PROBLEM CLUSTER at 10. See the note below the table.
A14: Culture | B14: Greeks | C14: =COUNTIFS(Proposal!$E$2:$E$107,$B14,Proposal!$F$2:$F$107,"<>NEW") | D14: =COUNTIFS(Proposal!$E$2:$E$107,$B14,Proposal!$G$2:$G$107,"Y") | E14: =D14-C14 | F14: =IF($D$16=0,0,D14/$D$16) | G14: UNDERWEIGHT at 3, and it is the cluster closest to the app's actual subject - the divergence angle is what the whole figure is built on. PI! is quietly the best teaching achievement in the app. Second place to spend a freed slot.
A15: Capstone | B15: Capstone | C15: =COUNTIFS(Proposal!$E$2:$E$107,$B15,Proposal!$F$2:$F$107,"<>NEW") | D15: =COUNTIFS(Proposal!$E$2:$E$107,$B15,Proposal!$G$2:$G$107,"Y") | E15: =D15-C15 | F15: =IF($D$16=0,0,D15/$D$16) | G15: UNITY!. Untouched.
B16: TOTAL | C16: =SUM(C5:C15) | D16: =SUM(D5:D15) | E16: =D16-C16 | F16: =IF(D16=0,0,D16/D16)
B18: XP check | C18: =(D16-1)*15+500 | D18: must equal 2000 - the Play Games cap | E18: =IF(C18=2000,"OK","OVER BUDGET by "&(C18-2000)&" XP - see DECISION NEEDED below")
B19: Revealed / Hidden | C19: =D5 | D19: =D16-D5 | E19: Tutorial ships Revealed, everything else Hidden (§12). Moves 16/85 -> 17/84, and the checker pins that number - free to change today, expensive after the Play Console is told.
A22: DECISION NEEDED: the list is at 102, not 101.
A24: You accepted GALLERY! and rejected DOUBLING! and THIRD!. That leaves three additions (DECOMPOSE!, TEMPTED!, GALLERY!) funded by two drops (CEILING!, MERSENNE!), so the total is 102 and XP is 2015 against a hard cap of 2000. One more drop is needed.
A26: Ranked candidates, all currently marked REVIEW on the Proposal tab:
A27: 1. GRACELAND! (901). The thinnest entry in the list - the blurb is one sentence, '901 is Memphis', and Elvis is the only hook. Nothing else in the design depends on it. This is my recommendation.
A28: 2. SUPERPRIME!. Worst effort-to-payoff ratio in the list: 11 taps returning the same 11 nodes, and no gild set can fix it. Costs you a genuinely intuitive idea, which is why it is second rather than first.
A29: 3. MEME! (67). The entry that ages fastest, and Play Games will not let you remove it later. Dropping it now is the only chance you get.
A31: I have NOT applied any of these - Scenario A still reads 102 so the gap stays visible. Flip one In A? cell to N and every count on this tab follows.
A34: Is the balance reasonable? Mostly yes, with two exceptions.
A36: Culture is 61% of the list (62 of 101). That is defensible: the Culture mechanic - recognise a number, work out its prime factors, watch it come apart - IS the app's core loop, and it is the most newbie-accessible thing in the design. Repeating it 62 times with good material is a reasonable bet.
A38: Math is 22% (22 of 101) for an app about integers. Lower than you might expect, but the Math entries carry far more weight per achievement - the relational ones gild 37 to 120 nodes each. I would not grow Math for its own sake; I would grow Puzzles and Greeks specifically, because those two are where 'intuition about integers' actually lives.
A40: Dial is the exception worth acting on. 10 of 101 - a tenth of the entire list - and:
A41: - No integer content whatsoever. The trigger is typing a number into a slider, which is the exact thing §1 calls 'entering a password' when it explains why twelve set-the-range achievements were cut. Dial is rescued by a fiction ('a phone number is a thing you dial'), and the fiction is charming, but it buys mechanics rather than meaning.
... A49: One more, not a distribution point: 13 of the 101 have no blurb at all, 12 of them in Meme and Lore. When we come back to the Wikipedia links, those 13 are the ones that need it most - for them the link is not a footnote, it is the entire explanation.

Sheet Collisions
A1: Trigger collisions - a correctness bug, separate from the rubric
A3: ACHIEVEMENTS.md §3 states the rule: 'No two achievements may share an exact selection trigger.' tools/check-achievements.mjs enforces it and passes 60 assertions - but it compares literal `sel` arrays against other literal `sel` arrays only.
A5: The relational predicates in achievements.js are never compared against the literal sets. pairWhere() accepts ANY exactly-two-prime selection, so every two-prime literal is a candidate. Seven currently double-fire, and CARDS! triple-fires:
A7: No | B7: Achievement | C7: Selection | D7: Also fires | E7: Cluster
A8: 45 | B8: CARDS! | C8: {3, 7} | D8: COUSINS!, GERMAIN! | E8: Meme
A9: 70 | B9: BEST! | C9: {37, 73} | D9: EMIRP! | E9: Geek
A10: 72 | B10: LIGHTSPEED! | C10: {13, 23} | D10: SQUARE UP! | E10: Geek
A11: 73 | B11: MEMORY! | C11: {2, 5} | D11: GERMAIN! | E11: Geek
A12: 75 | B12: INHERITED! | C12: {2, 23} | D12: SQUARE UP! | E12: Geek
A13: 85 | B13: QUARTER! | C13: {7, 13} | D13: SEXY! | E13: Calendar
A14: 86 | B14: SHORTEST! | C14: {2, 7} | D14: SQUARE UP! | E14: Calendar
A16: Also unbounded, and not in the table above:
A17: GOLDBACH! fires on any two primes summing to the current range, so it stacks on top of any of the seven above when the range happens to match.
A18: NEAT! fires on any two-prime selection containing 89 with the range at 178+.
A20: Whether this is a bug is a design call, not a code call:
A21: It may be a feature. Tapping {7,13} for QUARTER! and having SEXY! fire too is a small 'oh, that as well' - and by your rubric that is a genuine payoff, not a defect.
A22: It may be the failure §3 was written to prevent: two toasts at once, two clues rendered meaningless in one tap, and no way for the player to tell which action earned which.
A24: Either way the doc and the code currently disagree about whether the rule holds, and the checker reports green. If collisions are intended, the fix is to say so in §3 and §6 and assert the expected list in the checker - the same treatment ENIGMA! and SATOR! already get as recorded exceptions. If they are not intended, seven selections need changing.

Sheet UI changes
A1: Three changes that are not per-achievement data
A2: These live in achievements.js and in the data schema rather than in any one row, so they are here instead of on the Proposal tab.
A4: 1. Show the criteria once an achievement is unlocked
A5: Straightforward, and the data is already sitting there.
A6: The ask | B6: Display the criteria after unlock, because it is easy to arrive on one by accident.
A7: Verdict | B7: Do it. Every definition already carries `criteria` - Play Console requires a public description per achievement - and a comment at achievements.js:1318 explicitly says it stays on the definitions and must not be tidied away on the grounds that nothing displays it. This makes an existing field earn its keep, and there is no data change at all.
A8: The premise checks out | B8: Accidental arrival is not hypothetical, and it happens in at least four documented ways. (1) Seven two-prime selections also fire a relational predicate - see the Collisions tab. (2) GOLDBACH! and NEAT! stack on top of those whenever the range lines up. (3) ACHIEVEMENTS.md §8 records that selecting {5, 61} or {5, 83} reaches dials 305 and 415 with nobody having dialled, accepted as behaviour on 2026-08-23. (4) REST! fires on pausing the transport, which players will do for entirely unrelated reasons.
A9: Where | B9: In the earned-row body, between the clue and the blurb, so a row reads name / clue / criteria / blurb. Worth putting on the toast too (achievements.js:552) - the toast is the exact moment the player asks 'what did I just do?'.
A10: Cost | B10: One line at achievements.js:1332 and one at :552. Nothing else moves.
A13: 2. Tapping an achievement takes you to trophy room view
A14: Right instinct, and half the mechanism already exists - but the direct version would destroy the player's figure on every tap.
A15: What already happens | B15: setFocus() (achievements.js:865) calls fitFigureTo(), which raises N and switches all-integers on - but ONLY when something in the gild set is genuinely not being drawn - and it STASHES the previous values in rangeBeforeFocus / allIntBeforeFocus. restoreFigure() puts them back when focus clears. So 'tap to look, tap again to go back' is already the established pattern here. It is simply scoped to two knobs.
A16: The blocker | B16: applyTrophyRoom() (achievements.js:955) clicks #reset-btn first, which writes about forty DOM values by hand plus resetMorph() and resetCamera(), and stashes NOTHING. It is destructive by design, deliberately matching Dazzle (§9). Wire that to a row tap and every tap to read a blurb silently discards whatever the player had built, with no way back.
A17: It also reverses a decision already made | B17: ACHIEVEMENTS.md §5: 'The panel must not move on its own.' A peek that dropped the sheet on tap was built and then removed for reading as the panel jumping about for no reason. Auto-entering the trophy room is a much larger version of the same motion - worth re-deciding deliberately rather than by accident.
A18: Option A - make the trophy room reversible | B18: Snapshot the full config before applying and restore it when focus clears: the same shape as rangeBeforeFocus, just wider. Best result, most work - and §9's warning that 'reset does not reset everything' has already been a bug twice applies in reverse. A restore that misses a knob is the same class of bug, in the same place.
A19: Option B - an explicit control on the opened row [RECOMMENDED] | B19: Leave the tap light and reversible as it is, and put a 'see it in the trophy room' button inside the expanded row. Destructive stays consented, exactly as the cup and Dazzle already behave. Cheapest, consistent with the existing design, and it pairs with GALLERY!: the achievement teaches that the cup exists, and the row button gives a reason to press it.
A20: Option C - context-dependent | B20: If the player is already in trophy-room view, a tap refocuses in place; from the normal view it stays light. No new state to manage, but 'why did it behave differently that time' is a real cost.
A23: 3. Reference links
A24: Back on. 89 of 104 get one, and every title is verified against the live Wikipedia API.
A25: Coverage | B25: 89 of 104 achievements have a proposed link, in the 'Proposed link' column on the Proposal tab. The other 15 are jokes or UI furniture where no article adds anything - ORBS!, TRIPPY!, MEME! and so on.
A26: Verified, not guessed | B26: All 86 distinct article titles were checked against the Wikipedia API: every one exists, resolves directly, and none is a redirect or a disambiguation page. Eleven were corrected during that pass - CENTRAL! had been pointing at a disambiguation page, and every area-code article has been renamed since.
A27: Store it as a field, not inline HTML | B27: Put the article title, or the full URL, in its own `link` field. Blurbs are shared with the Play Console paste through tools/achievements-table.mjs, so markup written into blurb text would leak straight into that column.
A28: The plumbing decision is still real | B28: The app has no external links anywhere today, and @capacitor/browser is NOT installed - package.json carries only @capacitor/android and @capacitor/core. A bare <a href> inside the WebView navigates the app away with no way back, so this needs the Browser plugin or an appUrlOpen handler before the first link ships.
A29: Checker | B29: Assert every link is https, and that all 13 blurb-less achievements have one. A periodic title re-check is cheap: the whole set is two API calls.
A30: Priority | B30: The 13 achievements with NO blurb need this most - WHOLE!, MASONIC!, ENIGMA!, CATCH!, ROUTE!, CARDS!, JACKPOT!, SLURPEE!, JUMBO!, SPARTA!, LUCKY!, LOUDER! and MEME!. For those the link is not a footnote, it is the entire explanation.
